[2022-04-01 20:29:41,593] {taskinstance.py:903} INFO - Dependencies all met for <TaskInstance: divvybikes_elt_pipeline.upload_file_to_s3 2020-04-01T00:00:00+00:00 [queued]>
[2022-04-01 20:29:41,608] {taskinstance.py:903} INFO - Dependencies all met for <TaskInstance: divvybikes_elt_pipeline.upload_file_to_s3 2020-04-01T00:00:00+00:00 [queued]>
[2022-04-01 20:29:41,608] {taskinstance.py:1094} INFO - 
--------------------------------------------------------------------------------
[2022-04-01 20:29:41,608] {taskinstance.py:1095} INFO - Starting attempt 1 of 2
[2022-04-01 20:29:41,608] {taskinstance.py:1096} INFO - 
--------------------------------------------------------------------------------
[2022-04-01 20:29:41,617] {taskinstance.py:1114} INFO - Executing <Task(PythonOperator): upload_file_to_s3> on 2020-04-01T00:00:00+00:00
[2022-04-01 20:29:41,620] {standard_task_runner.py:52} INFO - Started process 32019 to run task
[2022-04-01 20:29:41,623] {standard_task_runner.py:76} INFO - Running: ['***', 'tasks', 'run', 'divvybikes_elt_pipeline', 'upload_file_to_s3', '2020-04-01T00:00:00+00:00', '--job-id', '92', '--pool', 'default_pool', '--raw', '--subdir', 'DAGS_FOLDER/extract_load.py', '--cfg-path', '/tmp/tmpj584571h', '--error-file', '/tmp/tmp_p526rmc']
[2022-04-01 20:29:41,624] {standard_task_runner.py:77} INFO - Job 92: Subtask upload_file_to_s3
[2022-04-01 20:29:41,655] {logging_mixin.py:109} INFO - Running <TaskInstance: divvybikes_elt_pipeline.upload_file_to_s3 2020-04-01T00:00:00+00:00 [running]> on host b399ffa6f3b6
[2022-04-01 20:29:41,692] {taskinstance.py:1253} INFO - Exporting the following env vars:
AIRFLOW_CTX_DAG_OWNER=***
AIRFLOW_CTX_DAG_ID=divvybikes_elt_pipeline
AIRFLOW_CTX_TASK_ID=upload_file_to_s3
AIRFLOW_CTX_EXECUTION_DATE=2020-04-01T00:00:00+00:00
AIRFLOW_CTX_DAG_RUN_ID=backfill__2020-04-01T00:00:00+00:00
[2022-04-01 20:29:41,693] {base_aws.py:396} INFO - Airflow Connection: aws_conn_id=s3_con
[2022-04-01 20:29:41,699] {base_aws.py:419} WARNING - Unable to use Airflow Connection for credentials.
[2022-04-01 20:29:41,699] {base_aws.py:420} INFO - Fallback on boto3 credential strategy
[2022-04-01 20:29:41,699] {base_aws.py:425} INFO - Creating session using boto3 credential strategy region_name=us-west-2
[2022-04-01 20:29:41,712] {credentials.py:1100} INFO - Found credentials in environment variables.
[2022-04-01 20:29:42,036] {taskinstance.py:1462} ERROR - Task failed with exception
Traceback (most recent call last):
  File "/home/airflow/.local/lib/python3.6/site-packages/airflow/models/taskinstance.py", line 1164, in _run_raw_task
    self._prepare_and_execute_task_with_callbacks(context, task)
  File "/home/airflow/.local/lib/python3.6/site-packages/airflow/models/taskinstance.py", line 1282, in _prepare_and_execute_task_with_callbacks
    result = self._execute_task(context, task_copy)
  File "/home/airflow/.local/lib/python3.6/site-packages/airflow/models/taskinstance.py", line 1312, in _execute_task
    result = task_copy.execute(context=context)
  File "/home/airflow/.local/lib/python3.6/site-packages/airflow/operators/python.py", line 150, in execute
    return_value = self.execute_callable()
  File "/home/airflow/.local/lib/python3.6/site-packages/airflow/operators/python.py", line 161, in execute_callable
    return self.python_callable(*self.op_args, **self.op_kwargs)
  File "/opt/airflow/dags/extract_load.py", line 98, in upload_to_s3
    hook.load_file(filename=filename, key=key, bucket_name=bucket_name)
  File "/home/airflow/.local/lib/python3.6/site-packages/airflow/providers/amazon/aws/hooks/s3.py", line 62, in wrapper
    return func(*bound_args.args, **bound_args.kwargs)
  File "/home/airflow/.local/lib/python3.6/site-packages/airflow/providers/amazon/aws/hooks/s3.py", line 91, in wrapper
    return func(*bound_args.args, **bound_args.kwargs)
  File "/home/airflow/.local/lib/python3.6/site-packages/airflow/providers/amazon/aws/hooks/s3.py", line 500, in load_file
    raise ValueError(f"The key {key} already exists.")
ValueError: The key 202004-divvy-tripdata.parquet already exists.
[2022-04-01 20:29:42,038] {taskinstance.py:1512} INFO - Marking task as UP_FOR_RETRY. dag_id=divvybikes_elt_pipeline, task_id=upload_file_to_s3, execution_date=20200401T000000, start_date=20220401T202941, end_date=20220401T202942
[2022-04-01 20:29:42,077] {local_task_job.py:151} INFO - Task exited with return code 1
[2022-04-01 20:29:42,095] {local_task_job.py:261} INFO - 0 downstream tasks scheduled from follow-on schedule check
